Data: 2018-01-26 21:38:31-------------------------------------------------------
Mensagem:-----------------------------------------------------------------------
Validation failed for one or more entities. See 'EntityValidationErrors' property for more details.
Source:-------------------------------------------------------------------------
EntityFramework
StackTrace:---------------------------------------------------------------------
   em System.Data.Entity.Internal.InternalContext.SaveChangesAsync(CancellationToken cancellationToken)
   em System.Data.Entity.Internal.LazyInternalContext.SaveChangesAsync(CancellationToken cancellationToken)
   em System.Data.Entity.DbContext.SaveChangesAsync(CancellationToken cancellationToken)
   em System.Data.Entity.DbContext.SaveChangesAsync()
   em FotUp.Models.ApplicationDbContext.<>n__0()
   em FotUp.Models.ApplicationDbContext.<SaveChangesAsync>d__32.MoveNext() na C:\Users\vitor\Dropbox\Projetos\FotUp\FotUp\FotUp\Models\IdentityModels.cs:linha 102
-Entidade do tipo "ApplicationUser" no estado "Added" tem os seguintes erros de validação:
--Property: "Celular", Valor: "(11) 98800-8036", Erro: "Celular Inválido"
================================================================================
Data: 2018-02-14 18:32:40-------------------------------------------------------
Mensagem:-----------------------------------------------------------------------
An error occurred while updating the entries. See the inner exception for details.
Source:-------------------------------------------------------------------------
mscorlib
StackTrace:---------------------------------------------------------------------
   em System.Runtime.CompilerServices.TaskAwaiter.ThrowForNonSuccess(Task task)
   em System.Runtime.CompilerServices.TaskAwaiter.HandleNonSuccessAndDebuggerNotification(Task task)
   em System.Runtime.CompilerServices.TaskAwaiter`1.GetResult()
   em FotUp.Infra.DbContext.ApplicationDbContext.<SaveChangesAsync>d__32.MoveNext() na C:\Users\vitor\Dropbox\Projetos\FotUp\FotUp\02-Infra\FotUp.Infra\DbContext\ApplicationDbContext.cs:linha 73
Mensagem:-----------------------------------------------------------------------
An error occurred while updating the entries. See the inner exception for details.
Source:-------------------------------------------------------------------------
EntityFramework
StackTrace:---------------------------------------------------------------------
   em System.Data.Entity.Core.Mapping.Update.Internal.UpdateTranslator.<UpdateAsync>d__0.MoveNext()
--- Fim do rastreamento de pilha do local anterior onde a exceção foi gerada ---
   em System.Runtime.CompilerServices.TaskAwaiter.ThrowForNonSuccess(Task task)
   em System.Runtime.CompilerServices.TaskAwaiter.HandleNonSuccessAndDebuggerNotification(Task task)
   em System.Data.Entity.Core.Objects.ObjectContext.<ExecuteInTransactionAsync>d__3d`1.MoveNext()
--- Fim do rastreamento de pilha do local anterior onde a exceção foi gerada ---
   em System.Runtime.CompilerServices.TaskAwaiter.ThrowForNonSuccess(Task task)
   em System.Runtime.CompilerServices.TaskAwaiter.HandleNonSuccessAndDebuggerNotification(Task task)
   em System.Data.Entity.Core.Objects.ObjectContext.<SaveChangesToStoreAsync>d__39.MoveNext()
--- Fim do rastreamento de pilha do local anterior onde a exceção foi gerada ---
   em System.Runtime.CompilerServices.TaskAwaiter.ThrowForNonSuccess(Task task)
   em System.Runtime.CompilerServices.TaskAwaiter.HandleNonSuccessAndDebuggerNotification(Task task)
   em System.Data.Entity.SqlServer.DefaultSqlExecutionStrategy.<ExecuteAsyncImplementation>d__9`1.MoveNext()
--- Fim do rastreamento de pilha do local anterior onde a exceção foi gerada ---
   em System.Runtime.CompilerServices.TaskAwaiter.ThrowForNonSuccess(Task task)
   em System.Runtime.CompilerServices.TaskAwaiter.HandleNonSuccessAndDebuggerNotification(Task task)
   em System.Data.Entity.Core.Objects.ObjectContext.<SaveChangesInternalAsync>d__31.MoveNext()
Mensagem:-----------------------------------------------------------------------
Não é possível inserir uma linha de chave duplicada no objeto 'dbo.TipoProduto' com índice exclusivo 'IX_Nome'. O valor de chave duplicada é (teste).
A instrução foi finalizada.
Source:-------------------------------------------------------------------------
.Net SqlClient Data Provider
StackTrace:---------------------------------------------------------------------
   em System.Data.SqlClient.SqlCommand.<>c.<ExecuteDbDataReaderAsync>b__174_0(Task`1 result)
   em System.Threading.Tasks.ContinuationResultTaskFromResultTask`2.InnerInvoke()
   em System.Threading.Tasks.Task.Execute()
--- Fim do rastreamento de pilha do local anterior onde a exceção foi gerada ---
   em System.Runtime.CompilerServices.TaskAwaiter.ThrowForNonSuccess(Task task)
   em System.Runtime.CompilerServices.TaskAwaiter.HandleNonSuccessAndDebuggerNotification(Task task)
   em System.Data.Entity.Utilities.TaskExtensions.CultureAwaiter`1.GetResult()
   em System.Data.Entity.Core.Mapping.Update.Internal.DynamicUpdateCommand.<ExecuteAsync>d__0.MoveNext()
--- Fim do rastreamento de pilha do local anterior onde a exceção foi gerada ---
   em System.Runtime.CompilerServices.TaskAwaiter.ThrowForNonSuccess(Task task)
   em System.Runtime.CompilerServices.TaskAwaiter.HandleNonSuccessAndDebuggerNotification(Task task)
   em System.Data.Entity.Core.Mapping.Update.Internal.UpdateTranslator.<UpdateAsync>d__0.MoveNext()
================================================================================
Data: 2018-02-14 19:03:16-------------------------------------------------------
Mensagem:-----------------------------------------------------------------------
An error occurred while updating the entries. See the inner exception for details.
Source:-------------------------------------------------------------------------
mscorlib
StackTrace:---------------------------------------------------------------------
   em System.Runtime.CompilerServices.TaskAwaiter.ThrowForNonSuccess(Task task)
   em System.Runtime.CompilerServices.TaskAwaiter.HandleNonSuccessAndDebuggerNotification(Task task)
   em System.Runtime.CompilerServices.TaskAwaiter`1.GetResult()
   em FotUp.Infra.DbContext.ApplicationDbContext.<SaveChangesAsync>d__32.MoveNext() na C:\Users\vitor\Dropbox\Projetos\FotUp\FotUp\02-Infra\FotUp.Infra\DbContext\ApplicationDbContext.cs:linha 73
Mensagem:-----------------------------------------------------------------------
An error occurred while updating the entries. See the inner exception for details.
Source:-------------------------------------------------------------------------
EntityFramework
StackTrace:---------------------------------------------------------------------
   em System.Data.Entity.Core.Mapping.Update.Internal.UpdateTranslator.<UpdateAsync>d__0.MoveNext()
--- Fim do rastreamento de pilha do local anterior onde a exceção foi gerada ---
   em System.Runtime.CompilerServices.TaskAwaiter.ThrowForNonSuccess(Task task)
   em System.Runtime.CompilerServices.TaskAwaiter.HandleNonSuccessAndDebuggerNotification(Task task)
   em System.Data.Entity.Core.Objects.ObjectContext.<ExecuteInTransactionAsync>d__3d`1.MoveNext()
--- Fim do rastreamento de pilha do local anterior onde a exceção foi gerada ---
   em System.Runtime.CompilerServices.TaskAwaiter.ThrowForNonSuccess(Task task)
   em System.Runtime.CompilerServices.TaskAwaiter.HandleNonSuccessAndDebuggerNotification(Task task)
   em System.Data.Entity.Core.Objects.ObjectContext.<SaveChangesToStoreAsync>d__39.MoveNext()
--- Fim do rastreamento de pilha do local anterior onde a exceção foi gerada ---
   em System.Runtime.CompilerServices.TaskAwaiter.ThrowForNonSuccess(Task task)
   em System.Runtime.CompilerServices.TaskAwaiter.HandleNonSuccessAndDebuggerNotification(Task task)
   em System.Data.Entity.SqlServer.DefaultSqlExecutionStrategy.<ExecuteAsyncImplementation>d__9`1.MoveNext()
--- Fim do rastreamento de pilha do local anterior onde a exceção foi gerada ---
   em System.Runtime.CompilerServices.TaskAwaiter.ThrowForNonSuccess(Task task)
   em System.Runtime.CompilerServices.TaskAwaiter.HandleNonSuccessAndDebuggerNotification(Task task)
   em System.Data.Entity.Core.Objects.ObjectContext.<SaveChangesInternalAsync>d__31.MoveNext()
Mensagem:-----------------------------------------------------------------------
Não é possível inserir uma linha de chave duplicada no objeto 'dbo.TipoProduto' com índice exclusivo 'IX_Nome'. O valor de chave duplicada é (teste).
A instrução foi finalizada.
Source:-------------------------------------------------------------------------
.Net SqlClient Data Provider
StackTrace:---------------------------------------------------------------------
   em System.Data.SqlClient.SqlCommand.<>c.<ExecuteDbDataReaderAsync>b__174_0(Task`1 result)
   em System.Threading.Tasks.ContinuationResultTaskFromResultTask`2.InnerInvoke()
   em System.Threading.Tasks.Task.Execute()
--- Fim do rastreamento de pilha do local anterior onde a exceção foi gerada ---
   em System.Runtime.CompilerServices.TaskAwaiter.ThrowForNonSuccess(Task task)
   em System.Runtime.CompilerServices.TaskAwaiter.HandleNonSuccessAndDebuggerNotification(Task task)
   em System.Data.Entity.Utilities.TaskExtensions.CultureAwaiter`1.GetResult()
   em System.Data.Entity.Core.Mapping.Update.Internal.DynamicUpdateCommand.<ExecuteAsync>d__0.MoveNext()
--- Fim do rastreamento de pilha do local anterior onde a exceção foi gerada ---
   em System.Runtime.CompilerServices.TaskAwaiter.ThrowForNonSuccess(Task task)
   em System.Runtime.CompilerServices.TaskAwaiter.HandleNonSuccessAndDebuggerNotification(Task task)
   em System.Data.Entity.Core.Mapping.Update.Internal.UpdateTranslator.<UpdateAsync>d__0.MoveNext()
================================================================================
Data: 2018-02-14 19:03:29-------------------------------------------------------
Mensagem:-----------------------------------------------------------------------
An error occurred while updating the entries. See the inner exception for details.
Source:-------------------------------------------------------------------------
mscorlib
StackTrace:---------------------------------------------------------------------
   em System.Runtime.CompilerServices.TaskAwaiter.ThrowForNonSuccess(Task task)
   em System.Runtime.CompilerServices.TaskAwaiter.HandleNonSuccessAndDebuggerNotification(Task task)
   em System.Runtime.CompilerServices.TaskAwaiter`1.GetResult()
   em FotUp.Infra.DbContext.ApplicationDbContext.<SaveChangesAsync>d__32.MoveNext() na C:\Users\vitor\Dropbox\Projetos\FotUp\FotUp\02-Infra\FotUp.Infra\DbContext\ApplicationDbContext.cs:linha 73
Mensagem:-----------------------------------------------------------------------
An error occurred while updating the entries. See the inner exception for details.
Source:-------------------------------------------------------------------------
EntityFramework
StackTrace:---------------------------------------------------------------------
   em System.Data.Entity.Core.Mapping.Update.Internal.UpdateTranslator.<UpdateAsync>d__0.MoveNext()
--- Fim do rastreamento de pilha do local anterior onde a exceção foi gerada ---
   em System.Runtime.CompilerServices.TaskAwaiter.ThrowForNonSuccess(Task task)
   em System.Runtime.CompilerServices.TaskAwaiter.HandleNonSuccessAndDebuggerNotification(Task task)
   em System.Data.Entity.Core.Objects.ObjectContext.<ExecuteInTransactionAsync>d__3d`1.MoveNext()
--- Fim do rastreamento de pilha do local anterior onde a exceção foi gerada ---
   em System.Runtime.CompilerServices.TaskAwaiter.ThrowForNonSuccess(Task task)
   em System.Runtime.CompilerServices.TaskAwaiter.HandleNonSuccessAndDebuggerNotification(Task task)
   em System.Data.Entity.Core.Objects.ObjectContext.<SaveChangesToStoreAsync>d__39.MoveNext()
--- Fim do rastreamento de pilha do local anterior onde a exceção foi gerada ---
   em System.Runtime.CompilerServices.TaskAwaiter.ThrowForNonSuccess(Task task)
   em System.Runtime.CompilerServices.TaskAwaiter.HandleNonSuccessAndDebuggerNotification(Task task)
   em System.Data.Entity.SqlServer.DefaultSqlExecutionStrategy.<ExecuteAsyncImplementation>d__9`1.MoveNext()
--- Fim do rastreamento de pilha do local anterior onde a exceção foi gerada ---
   em System.Runtime.CompilerServices.TaskAwaiter.ThrowForNonSuccess(Task task)
   em System.Runtime.CompilerServices.TaskAwaiter.HandleNonSuccessAndDebuggerNotification(Task task)
   em System.Data.Entity.Core.Objects.ObjectContext.<SaveChangesInternalAsync>d__31.MoveNext()
Mensagem:-----------------------------------------------------------------------
Não é possível inserir uma linha de chave duplicada no objeto 'dbo.TipoProduto' com índice exclusivo 'IX_Nome'. O valor de chave duplicada é (teste).
A instrução foi finalizada.
Source:-------------------------------------------------------------------------
.Net SqlClient Data Provider
StackTrace:---------------------------------------------------------------------
   em System.Data.SqlClient.SqlCommand.<>c.<ExecuteDbDataReaderAsync>b__174_0(Task`1 result)
   em System.Threading.Tasks.ContinuationResultTaskFromResultTask`2.InnerInvoke()
   em System.Threading.Tasks.Task.Execute()
--- Fim do rastreamento de pilha do local anterior onde a exceção foi gerada ---
   em System.Runtime.CompilerServices.TaskAwaiter.ThrowForNonSuccess(Task task)
   em System.Runtime.CompilerServices.TaskAwaiter.HandleNonSuccessAndDebuggerNotification(Task task)
   em System.Data.Entity.Utilities.TaskExtensions.CultureAwaiter`1.GetResult()
   em System.Data.Entity.Core.Mapping.Update.Internal.DynamicUpdateCommand.<ExecuteAsync>d__0.MoveNext()
--- Fim do rastreamento de pilha do local anterior onde a exceção foi gerada ---
   em System.Runtime.CompilerServices.TaskAwaiter.ThrowForNonSuccess(Task task)
   em System.Runtime.CompilerServices.TaskAwaiter.HandleNonSuccessAndDebuggerNotification(Task task)
   em System.Data.Entity.Core.Mapping.Update.Internal.UpdateTranslator.<UpdateAsync>d__0.MoveNext()
================================================================================
Data: 2018-02-14 19:03:48-------------------------------------------------------
Mensagem:-----------------------------------------------------------------------
An error occurred while updating the entries. See the inner exception for details.
Source:-------------------------------------------------------------------------
mscorlib
StackTrace:---------------------------------------------------------------------
   em System.Runtime.CompilerServices.TaskAwaiter.ThrowForNonSuccess(Task task)
   em System.Runtime.CompilerServices.TaskAwaiter.HandleNonSuccessAndDebuggerNotification(Task task)
   em System.Runtime.CompilerServices.TaskAwaiter`1.GetResult()
   em FotUp.Infra.DbContext.ApplicationDbContext.<SaveChangesAsync>d__32.MoveNext() na C:\Users\vitor\Dropbox\Projetos\FotUp\FotUp\02-Infra\FotUp.Infra\DbContext\ApplicationDbContext.cs:linha 73
Mensagem:-----------------------------------------------------------------------
An error occurred while updating the entries. See the inner exception for details.
Source:-------------------------------------------------------------------------
EntityFramework
StackTrace:---------------------------------------------------------------------
   em System.Data.Entity.Core.Mapping.Update.Internal.UpdateTranslator.<UpdateAsync>d__0.MoveNext()
--- Fim do rastreamento de pilha do local anterior onde a exceção foi gerada ---
   em System.Runtime.CompilerServices.TaskAwaiter.ThrowForNonSuccess(Task task)
   em System.Runtime.CompilerServices.TaskAwaiter.HandleNonSuccessAndDebuggerNotification(Task task)
   em System.Data.Entity.Core.Objects.ObjectContext.<ExecuteInTransactionAsync>d__3d`1.MoveNext()
--- Fim do rastreamento de pilha do local anterior onde a exceção foi gerada ---
   em System.Runtime.CompilerServices.TaskAwaiter.ThrowForNonSuccess(Task task)
   em System.Runtime.CompilerServices.TaskAwaiter.HandleNonSuccessAndDebuggerNotification(Task task)
   em System.Data.Entity.Core.Objects.ObjectContext.<SaveChangesToStoreAsync>d__39.MoveNext()
--- Fim do rastreamento de pilha do local anterior onde a exceção foi gerada ---
   em System.Runtime.CompilerServices.TaskAwaiter.ThrowForNonSuccess(Task task)
   em System.Runtime.CompilerServices.TaskAwaiter.HandleNonSuccessAndDebuggerNotification(Task task)
   em System.Data.Entity.SqlServer.DefaultSqlExecutionStrategy.<ExecuteAsyncImplementation>d__9`1.MoveNext()
--- Fim do rastreamento de pilha do local anterior onde a exceção foi gerada ---
   em System.Runtime.CompilerServices.TaskAwaiter.ThrowForNonSuccess(Task task)
   em System.Runtime.CompilerServices.TaskAwaiter.HandleNonSuccessAndDebuggerNotification(Task task)
   em System.Data.Entity.Core.Objects.ObjectContext.<SaveChangesInternalAsync>d__31.MoveNext()
Mensagem:-----------------------------------------------------------------------
Não é possível inserir uma linha de chave duplicada no objeto 'dbo.TipoProduto' com índice exclusivo 'IX_Nome'. O valor de chave duplicada é (teste).
A instrução foi finalizada.
Source:-------------------------------------------------------------------------
.Net SqlClient Data Provider
StackTrace:---------------------------------------------------------------------
   em System.Data.SqlClient.SqlCommand.<>c.<ExecuteDbDataReaderAsync>b__174_0(Task`1 result)
   em System.Threading.Tasks.ContinuationResultTaskFromResultTask`2.InnerInvoke()
   em System.Threading.Tasks.Task.Execute()
--- Fim do rastreamento de pilha do local anterior onde a exceção foi gerada ---
   em System.Runtime.CompilerServices.TaskAwaiter.ThrowForNonSuccess(Task task)
   em System.Runtime.CompilerServices.TaskAwaiter.HandleNonSuccessAndDebuggerNotification(Task task)
   em System.Data.Entity.Utilities.TaskExtensions.CultureAwaiter`1.GetResult()
   em System.Data.Entity.Core.Mapping.Update.Internal.DynamicUpdateCommand.<ExecuteAsync>d__0.MoveNext()
--- Fim do rastreamento de pilha do local anterior onde a exceção foi gerada ---
   em System.Runtime.CompilerServices.TaskAwaiter.ThrowForNonSuccess(Task task)
   em System.Runtime.CompilerServices.TaskAwaiter.HandleNonSuccessAndDebuggerNotification(Task task)
   em System.Data.Entity.Core.Mapping.Update.Internal.UpdateTranslator.<UpdateAsync>d__0.MoveNext()
================================================================================
Data: 2018-02-14 19:04:28-------------------------------------------------------
Mensagem:-----------------------------------------------------------------------
An error occurred while updating the entries. See the inner exception for details.
Source:-------------------------------------------------------------------------
mscorlib
StackTrace:---------------------------------------------------------------------
   em System.Runtime.CompilerServices.TaskAwaiter.ThrowForNonSuccess(Task task)
   em System.Runtime.CompilerServices.TaskAwaiter.HandleNonSuccessAndDebuggerNotification(Task task)
   em System.Runtime.CompilerServices.TaskAwaiter`1.GetResult()
   em FotUp.Infra.DbContext.ApplicationDbContext.<SaveChangesAsync>d__32.MoveNext() na C:\Users\vitor\Dropbox\Projetos\FotUp\FotUp\02-Infra\FotUp.Infra\DbContext\ApplicationDbContext.cs:linha 73
Mensagem:-----------------------------------------------------------------------
An error occurred while updating the entries. See the inner exception for details.
Source:-------------------------------------------------------------------------
EntityFramework
StackTrace:---------------------------------------------------------------------
   em System.Data.Entity.Core.Mapping.Update.Internal.UpdateTranslator.<UpdateAsync>d__0.MoveNext()
--- Fim do rastreamento de pilha do local anterior onde a exceção foi gerada ---
   em System.Runtime.CompilerServices.TaskAwaiter.ThrowForNonSuccess(Task task)
   em System.Runtime.CompilerServices.TaskAwaiter.HandleNonSuccessAndDebuggerNotification(Task task)
   em System.Data.Entity.Core.Objects.ObjectContext.<ExecuteInTransactionAsync>d__3d`1.MoveNext()
--- Fim do rastreamento de pilha do local anterior onde a exceção foi gerada ---
   em System.Runtime.CompilerServices.TaskAwaiter.ThrowForNonSuccess(Task task)
   em System.Runtime.CompilerServices.TaskAwaiter.HandleNonSuccessAndDebuggerNotification(Task task)
   em System.Data.Entity.Core.Objects.ObjectContext.<SaveChangesToStoreAsync>d__39.MoveNext()
--- Fim do rastreamento de pilha do local anterior onde a exceção foi gerada ---
   em System.Runtime.CompilerServices.TaskAwaiter.ThrowForNonSuccess(Task task)
   em System.Runtime.CompilerServices.TaskAwaiter.HandleNonSuccessAndDebuggerNotification(Task task)
   em System.Data.Entity.SqlServer.DefaultSqlExecutionStrategy.<ExecuteAsyncImplementation>d__9`1.MoveNext()
--- Fim do rastreamento de pilha do local anterior onde a exceção foi gerada ---
   em System.Runtime.CompilerServices.TaskAwaiter.ThrowForNonSuccess(Task task)
   em System.Runtime.CompilerServices.TaskAwaiter.HandleNonSuccessAndDebuggerNotification(Task task)
   em System.Data.Entity.Core.Objects.ObjectContext.<SaveChangesInternalAsync>d__31.MoveNext()
Mensagem:-----------------------------------------------------------------------
Não é possível inserir uma linha de chave duplicada no objeto 'dbo.TipoProduto' com índice exclusivo 'IX_Nome'. O valor de chave duplicada é (teste).
A instrução foi finalizada.
Source:-------------------------------------------------------------------------
.Net SqlClient Data Provider
StackTrace:---------------------------------------------------------------------
   em System.Data.SqlClient.SqlCommand.<>c.<ExecuteDbDataReaderAsync>b__174_0(Task`1 result)
   em System.Threading.Tasks.ContinuationResultTaskFromResultTask`2.InnerInvoke()
   em System.Threading.Tasks.Task.Execute()
--- Fim do rastreamento de pilha do local anterior onde a exceção foi gerada ---
   em System.Runtime.CompilerServices.TaskAwaiter.ThrowForNonSuccess(Task task)
   em System.Runtime.CompilerServices.TaskAwaiter.HandleNonSuccessAndDebuggerNotification(Task task)
   em System.Data.Entity.Utilities.TaskExtensions.CultureAwaiter`1.GetResult()
   em System.Data.Entity.Core.Mapping.Update.Internal.DynamicUpdateCommand.<ExecuteAsync>d__0.MoveNext()
--- Fim do rastreamento de pilha do local anterior onde a exceção foi gerada ---
   em System.Runtime.CompilerServices.TaskAwaiter.ThrowForNonSuccess(Task task)
   em System.Runtime.CompilerServices.TaskAwaiter.HandleNonSuccessAndDebuggerNotification(Task task)
   em System.Data.Entity.Core.Mapping.Update.Internal.UpdateTranslator.<UpdateAsync>d__0.MoveNext()
================================================================================
Data: 2018-02-24 17:00:39-------------------------------------------------------
Mensagem:-----------------------------------------------------------------------
An error occurred while updating the entries. See the inner exception for details.
Source:-------------------------------------------------------------------------
mscorlib
StackTrace:---------------------------------------------------------------------
   em System.Runtime.CompilerServices.TaskAwaiter.ThrowForNonSuccess(Task task)
   em System.Runtime.CompilerServices.TaskAwaiter.HandleNonSuccessAndDebuggerNotification(Task task)
   em System.Runtime.CompilerServices.TaskAwaiter`1.GetResult()
   em FotUp.Infra.DbContext.ApplicationDbContext.<SaveChangesAsync>d__32.MoveNext() na C:\Users\vitor\Dropbox\Projetos\FotUp\FotUp\02-Infra\FotUp.Infra\DbContext\ApplicationDbContext.cs:linha 73
Mensagem:-----------------------------------------------------------------------
An error occurred while updating the entries. See the inner exception for details.
Source:-------------------------------------------------------------------------
EntityFramework
StackTrace:---------------------------------------------------------------------
   em System.Data.Entity.Core.Mapping.Update.Internal.UpdateTranslator.<UpdateAsync>d__0.MoveNext()
--- Fim do rastreamento de pilha do local anterior onde a exceção foi gerada ---
   em System.Runtime.CompilerServices.TaskAwaiter.ThrowForNonSuccess(Task task)
   em System.Runtime.CompilerServices.TaskAwaiter.HandleNonSuccessAndDebuggerNotification(Task task)
   em System.Data.Entity.Core.Objects.ObjectContext.<ExecuteInTransactionAsync>d__3d`1.MoveNext()
--- Fim do rastreamento de pilha do local anterior onde a exceção foi gerada ---
   em System.Runtime.CompilerServices.TaskAwaiter.ThrowForNonSuccess(Task task)
   em System.Runtime.CompilerServices.TaskAwaiter.HandleNonSuccessAndDebuggerNotification(Task task)
   em System.Data.Entity.Core.Objects.ObjectContext.<SaveChangesToStoreAsync>d__39.MoveNext()
--- Fim do rastreamento de pilha do local anterior onde a exceção foi gerada ---
   em System.Runtime.CompilerServices.TaskAwaiter.ThrowForNonSuccess(Task task)
   em System.Runtime.CompilerServices.TaskAwaiter.HandleNonSuccessAndDebuggerNotification(Task task)
   em System.Data.Entity.SqlServer.DefaultSqlExecutionStrategy.<ExecuteAsyncImplementation>d__9`1.MoveNext()
--- Fim do rastreamento de pilha do local anterior onde a exceção foi gerada ---
   em System.Runtime.CompilerServices.TaskAwaiter.ThrowForNonSuccess(Task task)
   em System.Runtime.CompilerServices.TaskAwaiter.HandleNonSuccessAndDebuggerNotification(Task task)
   em System.Data.Entity.Core.Objects.ObjectContext.<SaveChangesInternalAsync>d__31.MoveNext()
Mensagem:-----------------------------------------------------------------------
A conversão de um tipo de dados datetime2 em um tipo de dados datetime resultou em um valor fora do intervalo.
A instrução foi finalizada.
Source:-------------------------------------------------------------------------
.Net SqlClient Data Provider
StackTrace:---------------------------------------------------------------------
   em System.Data.SqlClient.SqlCommand.<>c.<ExecuteDbDataReaderAsync>b__174_0(Task`1 result)
   em System.Threading.Tasks.ContinuationResultTaskFromResultTask`2.InnerInvoke()
   em System.Threading.Tasks.Task.Execute()
--- Fim do rastreamento de pilha do local anterior onde a exceção foi gerada ---
   em System.Runtime.CompilerServices.TaskAwaiter.ThrowForNonSuccess(Task task)
   em System.Runtime.CompilerServices.TaskAwaiter.HandleNonSuccessAndDebuggerNotification(Task task)
   em System.Data.Entity.Utilities.TaskExtensions.CultureAwaiter`1.GetResult()
   em System.Data.Entity.Core.Mapping.Update.Internal.DynamicUpdateCommand.<ExecuteAsync>d__0.MoveNext()
--- Fim do rastreamento de pilha do local anterior onde a exceção foi gerada ---
   em System.Runtime.CompilerServices.TaskAwaiter.ThrowForNonSuccess(Task task)
   em System.Runtime.CompilerServices.TaskAwaiter.HandleNonSuccessAndDebuggerNotification(Task task)
   em System.Data.Entity.Core.Mapping.Update.Internal.UpdateTranslator.<UpdateAsync>d__0.MoveNext()
================================================================================
Data: 2018-02-24 17:01:58-------------------------------------------------------
Mensagem:-----------------------------------------------------------------------
An error occurred while updating the entries. See the inner exception for details.
Source:-------------------------------------------------------------------------
mscorlib
StackTrace:---------------------------------------------------------------------
   em System.Runtime.CompilerServices.TaskAwaiter.ThrowForNonSuccess(Task task)
   em System.Runtime.CompilerServices.TaskAwaiter.HandleNonSuccessAndDebuggerNotification(Task task)
   em System.Runtime.CompilerServices.TaskAwaiter`1.GetResult()
   em FotUp.Infra.DbContext.ApplicationDbContext.<SaveChangesAsync>d__32.MoveNext() na C:\Users\vitor\Dropbox\Projetos\FotUp\FotUp\02-Infra\FotUp.Infra\DbContext\ApplicationDbContext.cs:linha 73
Mensagem:-----------------------------------------------------------------------
An error occurred while updating the entries. See the inner exception for details.
Source:-------------------------------------------------------------------------
EntityFramework
StackTrace:---------------------------------------------------------------------
   em System.Data.Entity.Core.Mapping.Update.Internal.UpdateTranslator.<UpdateAsync>d__0.MoveNext()
--- Fim do rastreamento de pilha do local anterior onde a exceção foi gerada ---
   em System.Runtime.CompilerServices.TaskAwaiter.ThrowForNonSuccess(Task task)
   em System.Runtime.CompilerServices.TaskAwaiter.HandleNonSuccessAndDebuggerNotification(Task task)
   em System.Data.Entity.Core.Objects.ObjectContext.<ExecuteInTransactionAsync>d__3d`1.MoveNext()
--- Fim do rastreamento de pilha do local anterior onde a exceção foi gerada ---
   em System.Runtime.CompilerServices.TaskAwaiter.ThrowForNonSuccess(Task task)
   em System.Runtime.CompilerServices.TaskAwaiter.HandleNonSuccessAndDebuggerNotification(Task task)
   em System.Data.Entity.Core.Objects.ObjectContext.<SaveChangesToStoreAsync>d__39.MoveNext()
--- Fim do rastreamento de pilha do local anterior onde a exceção foi gerada ---
   em System.Runtime.CompilerServices.TaskAwaiter.ThrowForNonSuccess(Task task)
   em System.Runtime.CompilerServices.TaskAwaiter.HandleNonSuccessAndDebuggerNotification(Task task)
   em System.Data.Entity.SqlServer.DefaultSqlExecutionStrategy.<ExecuteAsyncImplementation>d__9`1.MoveNext()
--- Fim do rastreamento de pilha do local anterior onde a exceção foi gerada ---
   em System.Runtime.CompilerServices.TaskAwaiter.ThrowForNonSuccess(Task task)
   em System.Runtime.CompilerServices.TaskAwaiter.HandleNonSuccessAndDebuggerNotification(Task task)
   em System.Data.Entity.Core.Objects.ObjectContext.<SaveChangesInternalAsync>d__31.MoveNext()
Mensagem:-----------------------------------------------------------------------
A conversão de um tipo de dados datetime2 em um tipo de dados datetime resultou em um valor fora do intervalo.
A instrução foi finalizada.
Source:-------------------------------------------------------------------------
.Net SqlClient Data Provider
StackTrace:---------------------------------------------------------------------
   em System.Data.SqlClient.SqlCommand.<>c.<ExecuteDbDataReaderAsync>b__174_0(Task`1 result)
   em System.Threading.Tasks.ContinuationResultTaskFromResultTask`2.InnerInvoke()
   em System.Threading.Tasks.Task.Execute()
--- Fim do rastreamento de pilha do local anterior onde a exceção foi gerada ---
   em System.Runtime.CompilerServices.TaskAwaiter.ThrowForNonSuccess(Task task)
   em System.Runtime.CompilerServices.TaskAwaiter.HandleNonSuccessAndDebuggerNotification(Task task)
   em System.Data.Entity.Utilities.TaskExtensions.CultureAwaiter`1.GetResult()
   em System.Data.Entity.Core.Mapping.Update.Internal.DynamicUpdateCommand.<ExecuteAsync>d__0.MoveNext()
--- Fim do rastreamento de pilha do local anterior onde a exceção foi gerada ---
   em System.Runtime.CompilerServices.TaskAwaiter.ThrowForNonSuccess(Task task)
   em System.Runtime.CompilerServices.TaskAwaiter.HandleNonSuccessAndDebuggerNotification(Task task)
   em System.Data.Entity.Core.Mapping.Update.Internal.UpdateTranslator.<UpdateAsync>d__0.MoveNext()
================================================================================
Data: 2018-02-24 17:02:14-------------------------------------------------------
Mensagem:-----------------------------------------------------------------------
An error occurred while updating the entries. See the inner exception for details.
Source:-------------------------------------------------------------------------
mscorlib
StackTrace:---------------------------------------------------------------------
   em System.Runtime.CompilerServices.TaskAwaiter.ThrowForNonSuccess(Task task)
   em System.Runtime.CompilerServices.TaskAwaiter.HandleNonSuccessAndDebuggerNotification(Task task)
   em System.Runtime.CompilerServices.TaskAwaiter`1.GetResult()
   em FotUp.Infra.DbContext.ApplicationDbContext.<SaveChangesAsync>d__32.MoveNext() na C:\Users\vitor\Dropbox\Projetos\FotUp\FotUp\02-Infra\FotUp.Infra\DbContext\ApplicationDbContext.cs:linha 73
Mensagem:-----------------------------------------------------------------------
An error occurred while updating the entries. See the inner exception for details.
Source:-------------------------------------------------------------------------
EntityFramework
StackTrace:---------------------------------------------------------------------
   em System.Data.Entity.Core.Mapping.Update.Internal.UpdateTranslator.<UpdateAsync>d__0.MoveNext()
--- Fim do rastreamento de pilha do local anterior onde a exceção foi gerada ---
   em System.Runtime.CompilerServices.TaskAwaiter.ThrowForNonSuccess(Task task)
   em System.Runtime.CompilerServices.TaskAwaiter.HandleNonSuccessAndDebuggerNotification(Task task)
   em System.Data.Entity.Core.Objects.ObjectContext.<ExecuteInTransactionAsync>d__3d`1.MoveNext()
--- Fim do rastreamento de pilha do local anterior onde a exceção foi gerada ---
   em System.Runtime.CompilerServices.TaskAwaiter.ThrowForNonSuccess(Task task)
   em System.Runtime.CompilerServices.TaskAwaiter.HandleNonSuccessAndDebuggerNotification(Task task)
   em System.Data.Entity.Core.Objects.ObjectContext.<SaveChangesToStoreAsync>d__39.MoveNext()
--- Fim do rastreamento de pilha do local anterior onde a exceção foi gerada ---
   em System.Runtime.CompilerServices.TaskAwaiter.ThrowForNonSuccess(Task task)
   em System.Runtime.CompilerServices.TaskAwaiter.HandleNonSuccessAndDebuggerNotification(Task task)
   em System.Data.Entity.SqlServer.DefaultSqlExecutionStrategy.<ExecuteAsyncImplementation>d__9`1.MoveNext()
--- Fim do rastreamento de pilha do local anterior onde a exceção foi gerada ---
   em System.Runtime.CompilerServices.TaskAwaiter.ThrowForNonSuccess(Task task)
   em System.Runtime.CompilerServices.TaskAwaiter.HandleNonSuccessAndDebuggerNotification(Task task)
   em System.Data.Entity.Core.Objects.ObjectContext.<SaveChangesInternalAsync>d__31.MoveNext()
Mensagem:-----------------------------------------------------------------------
A conversão de um tipo de dados datetime2 em um tipo de dados datetime resultou em um valor fora do intervalo.
A instrução foi finalizada.
Source:-------------------------------------------------------------------------
.Net SqlClient Data Provider
StackTrace:---------------------------------------------------------------------
   em System.Data.SqlClient.SqlCommand.<>c.<ExecuteDbDataReaderAsync>b__174_0(Task`1 result)
   em System.Threading.Tasks.ContinuationResultTaskFromResultTask`2.InnerInvoke()
   em System.Threading.Tasks.Task.Execute()
--- Fim do rastreamento de pilha do local anterior onde a exceção foi gerada ---
   em System.Runtime.CompilerServices.TaskAwaiter.ThrowForNonSuccess(Task task)
   em System.Runtime.CompilerServices.TaskAwaiter.HandleNonSuccessAndDebuggerNotification(Task task)
   em System.Data.Entity.Utilities.TaskExtensions.CultureAwaiter`1.GetResult()
   em System.Data.Entity.Core.Mapping.Update.Internal.DynamicUpdateCommand.<ExecuteAsync>d__0.MoveNext()
--- Fim do rastreamento de pilha do local anterior onde a exceção foi gerada ---
   em System.Runtime.CompilerServices.TaskAwaiter.ThrowForNonSuccess(Task task)
   em System.Runtime.CompilerServices.TaskAwaiter.HandleNonSuccessAndDebuggerNotification(Task task)
   em System.Data.Entity.Core.Mapping.Update.Internal.UpdateTranslator.<UpdateAsync>d__0.MoveNext()
================================================================================
Data: 2018-02-24 17:02:33-------------------------------------------------------
Mensagem:-----------------------------------------------------------------------
An error occurred while updating the entries. See the inner exception for details.
Source:-------------------------------------------------------------------------
mscorlib
StackTrace:---------------------------------------------------------------------
   em System.Runtime.CompilerServices.TaskAwaiter.ThrowForNonSuccess(Task task)
   em System.Runtime.CompilerServices.TaskAwaiter.HandleNonSuccessAndDebuggerNotification(Task task)
   em System.Runtime.CompilerServices.TaskAwaiter`1.GetResult()
   em FotUp.Infra.DbContext.ApplicationDbContext.<SaveChangesAsync>d__32.MoveNext() na C:\Users\vitor\Dropbox\Projetos\FotUp\FotUp\02-Infra\FotUp.Infra\DbContext\ApplicationDbContext.cs:linha 73
Mensagem:-----------------------------------------------------------------------
An error occurred while updating the entries. See the inner exception for details.
Source:-------------------------------------------------------------------------
EntityFramework
StackTrace:---------------------------------------------------------------------
   em System.Data.Entity.Core.Mapping.Update.Internal.UpdateTranslator.<UpdateAsync>d__0.MoveNext()
--- Fim do rastreamento de pilha do local anterior onde a exceção foi gerada ---
   em System.Runtime.CompilerServices.TaskAwaiter.ThrowForNonSuccess(Task task)
   em System.Runtime.CompilerServices.TaskAwaiter.HandleNonSuccessAndDebuggerNotification(Task task)
   em System.Data.Entity.Core.Objects.ObjectContext.<ExecuteInTransactionAsync>d__3d`1.MoveNext()
--- Fim do rastreamento de pilha do local anterior onde a exceção foi gerada ---
   em System.Runtime.CompilerServices.TaskAwaiter.ThrowForNonSuccess(Task task)
   em System.Runtime.CompilerServices.TaskAwaiter.HandleNonSuccessAndDebuggerNotification(Task task)
   em System.Data.Entity.Core.Objects.ObjectContext.<SaveChangesToStoreAsync>d__39.MoveNext()
--- Fim do rastreamento de pilha do local anterior onde a exceção foi gerada ---
   em System.Runtime.CompilerServices.TaskAwaiter.ThrowForNonSuccess(Task task)
   em System.Runtime.CompilerServices.TaskAwaiter.HandleNonSuccessAndDebuggerNotification(Task task)
   em System.Data.Entity.SqlServer.DefaultSqlExecutionStrategy.<ExecuteAsyncImplementation>d__9`1.MoveNext()
--- Fim do rastreamento de pilha do local anterior onde a exceção foi gerada ---
   em System.Runtime.CompilerServices.TaskAwaiter.ThrowForNonSuccess(Task task)
   em System.Runtime.CompilerServices.TaskAwaiter.HandleNonSuccessAndDebuggerNotification(Task task)
   em System.Data.Entity.Core.Objects.ObjectContext.<SaveChangesInternalAsync>d__31.MoveNext()
Mensagem:-----------------------------------------------------------------------
A conversão de um tipo de dados datetime2 em um tipo de dados datetime resultou em um valor fora do intervalo.
A instrução foi finalizada.
Source:-------------------------------------------------------------------------
.Net SqlClient Data Provider
StackTrace:---------------------------------------------------------------------
   em System.Data.SqlClient.SqlCommand.<>c.<ExecuteDbDataReaderAsync>b__174_0(Task`1 result)
   em System.Threading.Tasks.ContinuationResultTaskFromResultTask`2.InnerInvoke()
   em System.Threading.Tasks.Task.Execute()
--- Fim do rastreamento de pilha do local anterior onde a exceção foi gerada ---
   em System.Runtime.CompilerServices.TaskAwaiter.ThrowForNonSuccess(Task task)
   em System.Runtime.CompilerServices.TaskAwaiter.HandleNonSuccessAndDebuggerNotification(Task task)
   em System.Data.Entity.Utilities.TaskExtensions.CultureAwaiter`1.GetResult()
   em System.Data.Entity.Core.Mapping.Update.Internal.DynamicUpdateCommand.<ExecuteAsync>d__0.MoveNext()
--- Fim do rastreamento de pilha do local anterior onde a exceção foi gerada ---
   em System.Runtime.CompilerServices.TaskAwaiter.ThrowForNonSuccess(Task task)
   em System.Runtime.CompilerServices.TaskAwaiter.HandleNonSuccessAndDebuggerNotification(Task task)
   em System.Data.Entity.Core.Mapping.Update.Internal.UpdateTranslator.<UpdateAsync>d__0.MoveNext()
================================================================================
Data: 2018-02-24 17:02:51-------------------------------------------------------
Mensagem:-----------------------------------------------------------------------
An error occurred while updating the entries. See the inner exception for details.
Source:-------------------------------------------------------------------------
mscorlib
StackTrace:---------------------------------------------------------------------
   em System.Runtime.CompilerServices.TaskAwaiter.ThrowForNonSuccess(Task task)
   em System.Runtime.CompilerServices.TaskAwaiter.HandleNonSuccessAndDebuggerNotification(Task task)
   em System.Runtime.CompilerServices.TaskAwaiter`1.GetResult()
   em FotUp.Infra.DbContext.ApplicationDbContext.<SaveChangesAsync>d__32.MoveNext() na C:\Users\vitor\Dropbox\Projetos\FotUp\FotUp\02-Infra\FotUp.Infra\DbContext\ApplicationDbContext.cs:linha 73
Mensagem:-----------------------------------------------------------------------
An error occurred while updating the entries. See the inner exception for details.
Source:-------------------------------------------------------------------------
EntityFramework
StackTrace:---------------------------------------------------------------------
   em System.Data.Entity.Core.Mapping.Update.Internal.UpdateTranslator.<UpdateAsync>d__0.MoveNext()
--- Fim do rastreamento de pilha do local anterior onde a exceção foi gerada ---
   em System.Runtime.CompilerServices.TaskAwaiter.ThrowForNonSuccess(Task task)
   em System.Runtime.CompilerServices.TaskAwaiter.HandleNonSuccessAndDebuggerNotification(Task task)
   em System.Data.Entity.Core.Objects.ObjectContext.<ExecuteInTransactionAsync>d__3d`1.MoveNext()
--- Fim do rastreamento de pilha do local anterior onde a exceção foi gerada ---
   em System.Runtime.CompilerServices.TaskAwaiter.ThrowForNonSuccess(Task task)
   em System.Runtime.CompilerServices.TaskAwaiter.HandleNonSuccessAndDebuggerNotification(Task task)
   em System.Data.Entity.Core.Objects.ObjectContext.<SaveChangesToStoreAsync>d__39.MoveNext()
--- Fim do rastreamento de pilha do local anterior onde a exceção foi gerada ---
   em System.Runtime.CompilerServices.TaskAwaiter.ThrowForNonSuccess(Task task)
   em System.Runtime.CompilerServices.TaskAwaiter.HandleNonSuccessAndDebuggerNotification(Task task)
   em System.Data.Entity.SqlServer.DefaultSqlExecutionStrategy.<ExecuteAsyncImplementation>d__9`1.MoveNext()
--- Fim do rastreamento de pilha do local anterior onde a exceção foi gerada ---
   em System.Runtime.CompilerServices.TaskAwaiter.ThrowForNonSuccess(Task task)
   em System.Runtime.CompilerServices.TaskAwaiter.HandleNonSuccessAndDebuggerNotification(Task task)
   em System.Data.Entity.Core.Objects.ObjectContext.<SaveChangesInternalAsync>d__31.MoveNext()
Mensagem:-----------------------------------------------------------------------
A conversão de um tipo de dados datetime2 em um tipo de dados datetime resultou em um valor fora do intervalo.
A instrução foi finalizada.
Source:-------------------------------------------------------------------------
.Net SqlClient Data Provider
StackTrace:---------------------------------------------------------------------
   em System.Data.SqlClient.SqlCommand.<>c.<ExecuteDbDataReaderAsync>b__174_0(Task`1 result)
   em System.Threading.Tasks.ContinuationResultTaskFromResultTask`2.InnerInvoke()
   em System.Threading.Tasks.Task.Execute()
--- Fim do rastreamento de pilha do local anterior onde a exceção foi gerada ---
   em System.Runtime.CompilerServices.TaskAwaiter.ThrowForNonSuccess(Task task)
   em System.Runtime.CompilerServices.TaskAwaiter.HandleNonSuccessAndDebuggerNotification(Task task)
   em System.Data.Entity.Utilities.TaskExtensions.CultureAwaiter`1.GetResult()
   em System.Data.Entity.Core.Mapping.Update.Internal.DynamicUpdateCommand.<ExecuteAsync>d__0.MoveNext()
--- Fim do rastreamento de pilha do local anterior onde a exceção foi gerada ---
   em System.Runtime.CompilerServices.TaskAwaiter.ThrowForNonSuccess(Task task)
   em System.Runtime.CompilerServices.TaskAwaiter.HandleNonSuccessAndDebuggerNotification(Task task)
   em System.Data.Entity.Core.Mapping.Update.Internal.UpdateTranslator.<UpdateAsync>d__0.MoveNext()
================================================================================
Data: 2018-02-24 17:04:27-------------------------------------------------------
Mensagem:-----------------------------------------------------------------------
An error occurred while updating the entries. See the inner exception for details.
Source:-------------------------------------------------------------------------
mscorlib
StackTrace:---------------------------------------------------------------------
   em System.Runtime.CompilerServices.TaskAwaiter.ThrowForNonSuccess(Task task)
   em System.Runtime.CompilerServices.TaskAwaiter.HandleNonSuccessAndDebuggerNotification(Task task)
   em System.Runtime.CompilerServices.TaskAwaiter`1.GetResult()
   em FotUp.Infra.DbContext.ApplicationDbContext.<SaveChangesAsync>d__32.MoveNext() na C:\Users\vitor\Dropbox\Projetos\FotUp\FotUp\02-Infra\FotUp.Infra\DbContext\ApplicationDbContext.cs:linha 73
Mensagem:-----------------------------------------------------------------------
An error occurred while updating the entries. See the inner exception for details.
Source:-------------------------------------------------------------------------
EntityFramework
StackTrace:---------------------------------------------------------------------
   em System.Data.Entity.Core.Mapping.Update.Internal.UpdateTranslator.<UpdateAsync>d__0.MoveNext()
--- Fim do rastreamento de pilha do local anterior onde a exceção foi gerada ---
   em System.Runtime.CompilerServices.TaskAwaiter.ThrowForNonSuccess(Task task)
   em System.Runtime.CompilerServices.TaskAwaiter.HandleNonSuccessAndDebuggerNotification(Task task)
   em System.Data.Entity.Core.Objects.ObjectContext.<ExecuteInTransactionAsync>d__3d`1.MoveNext()
--- Fim do rastreamento de pilha do local anterior onde a exceção foi gerada ---
   em System.Runtime.CompilerServices.TaskAwaiter.ThrowForNonSuccess(Task task)
   em System.Runtime.CompilerServices.TaskAwaiter.HandleNonSuccessAndDebuggerNotification(Task task)
   em System.Data.Entity.Core.Objects.ObjectContext.<SaveChangesToStoreAsync>d__39.MoveNext()
--- Fim do rastreamento de pilha do local anterior onde a exceção foi gerada ---
   em System.Runtime.CompilerServices.TaskAwaiter.ThrowForNonSuccess(Task task)
   em System.Runtime.CompilerServices.TaskAwaiter.HandleNonSuccessAndDebuggerNotification(Task task)
   em System.Data.Entity.SqlServer.DefaultSqlExecutionStrategy.<ExecuteAsyncImplementation>d__9`1.MoveNext()
--- Fim do rastreamento de pilha do local anterior onde a exceção foi gerada ---
   em System.Runtime.CompilerServices.TaskAwaiter.ThrowForNonSuccess(Task task)
   em System.Runtime.CompilerServices.TaskAwaiter.HandleNonSuccessAndDebuggerNotification(Task task)
   em System.Data.Entity.Core.Objects.ObjectContext.<SaveChangesInternalAsync>d__31.MoveNext()
Mensagem:-----------------------------------------------------------------------
A conversão de um tipo de dados datetime2 em um tipo de dados datetime resultou em um valor fora do intervalo.
A instrução foi finalizada.
Source:-------------------------------------------------------------------------
.Net SqlClient Data Provider
StackTrace:---------------------------------------------------------------------
   em System.Data.SqlClient.SqlCommand.<>c.<ExecuteDbDataReaderAsync>b__174_0(Task`1 result)
   em System.Threading.Tasks.ContinuationResultTaskFromResultTask`2.InnerInvoke()
   em System.Threading.Tasks.Task.Execute()
--- Fim do rastreamento de pilha do local anterior onde a exceção foi gerada ---
   em System.Runtime.CompilerServices.TaskAwaiter.ThrowForNonSuccess(Task task)
   em System.Runtime.CompilerServices.TaskAwaiter.HandleNonSuccessAndDebuggerNotification(Task task)
   em System.Data.Entity.Utilities.TaskExtensions.CultureAwaiter`1.GetResult()
   em System.Data.Entity.Core.Mapping.Update.Internal.DynamicUpdateCommand.<ExecuteAsync>d__0.MoveNext()
--- Fim do rastreamento de pilha do local anterior onde a exceção foi gerada ---
   em System.Runtime.CompilerServices.TaskAwaiter.ThrowForNonSuccess(Task task)
   em System.Runtime.CompilerServices.TaskAwaiter.HandleNonSuccessAndDebuggerNotification(Task task)
   em System.Data.Entity.Core.Mapping.Update.Internal.UpdateTranslator.<UpdateAsync>d__0.MoveNext()
================================================================================
Data: 2018-02-24 17:08:09-------------------------------------------------------
Mensagem:-----------------------------------------------------------------------
An error occurred while updating the entries. See the inner exception for details.
Source:-------------------------------------------------------------------------
mscorlib
StackTrace:---------------------------------------------------------------------
   em System.Runtime.CompilerServices.TaskAwaiter.ThrowForNonSuccess(Task task)
   em System.Runtime.CompilerServices.TaskAwaiter.HandleNonSuccessAndDebuggerNotification(Task task)
   em System.Runtime.CompilerServices.TaskAwaiter`1.GetResult()
   em FotUp.Infra.DbContext.ApplicationDbContext.<SaveChangesAsync>d__32.MoveNext() na C:\Users\vitor\Dropbox\Projetos\FotUp\FotUp\02-Infra\FotUp.Infra\DbContext\ApplicationDbContext.cs:linha 73
Mensagem:-----------------------------------------------------------------------
An error occurred while updating the entries. See the inner exception for details.
Source:-------------------------------------------------------------------------
EntityFramework
StackTrace:---------------------------------------------------------------------
   em System.Data.Entity.Core.Mapping.Update.Internal.UpdateTranslator.<UpdateAsync>d__0.MoveNext()
--- Fim do rastreamento de pilha do local anterior onde a exceção foi gerada ---
   em System.Runtime.CompilerServices.TaskAwaiter.ThrowForNonSuccess(Task task)
   em System.Runtime.CompilerServices.TaskAwaiter.HandleNonSuccessAndDebuggerNotification(Task task)
   em System.Data.Entity.Core.Objects.ObjectContext.<ExecuteInTransactionAsync>d__3d`1.MoveNext()
--- Fim do rastreamento de pilha do local anterior onde a exceção foi gerada ---
   em System.Runtime.CompilerServices.TaskAwaiter.ThrowForNonSuccess(Task task)
   em System.Runtime.CompilerServices.TaskAwaiter.HandleNonSuccessAndDebuggerNotification(Task task)
   em System.Data.Entity.Core.Objects.ObjectContext.<SaveChangesToStoreAsync>d__39.MoveNext()
--- Fim do rastreamento de pilha do local anterior onde a exceção foi gerada ---
   em System.Runtime.CompilerServices.TaskAwaiter.ThrowForNonSuccess(Task task)
   em System.Runtime.CompilerServices.TaskAwaiter.HandleNonSuccessAndDebuggerNotification(Task task)
   em System.Data.Entity.SqlServer.DefaultSqlExecutionStrategy.<ExecuteAsyncImplementation>d__9`1.MoveNext()
--- Fim do rastreamento de pilha do local anterior onde a exceção foi gerada ---
   em System.Runtime.CompilerServices.TaskAwaiter.ThrowForNonSuccess(Task task)
   em System.Runtime.CompilerServices.TaskAwaiter.HandleNonSuccessAndDebuggerNotification(Task task)
   em System.Data.Entity.Core.Objects.ObjectContext.<SaveChangesInternalAsync>d__31.MoveNext()
Mensagem:-----------------------------------------------------------------------
A conversão de um tipo de dados datetime2 em um tipo de dados datetime resultou em um valor fora do intervalo.
A instrução foi finalizada.
Source:-------------------------------------------------------------------------
.Net SqlClient Data Provider
StackTrace:---------------------------------------------------------------------
   em System.Data.SqlClient.SqlCommand.<>c.<ExecuteDbDataReaderAsync>b__174_0(Task`1 result)
   em System.Threading.Tasks.ContinuationResultTaskFromResultTask`2.InnerInvoke()
   em System.Threading.Tasks.Task.Execute()
--- Fim do rastreamento de pilha do local anterior onde a exceção foi gerada ---
   em System.Runtime.CompilerServices.TaskAwaiter.ThrowForNonSuccess(Task task)
   em System.Runtime.CompilerServices.TaskAwaiter.HandleNonSuccessAndDebuggerNotification(Task task)
   em System.Data.Entity.Utilities.TaskExtensions.CultureAwaiter`1.GetResult()
   em System.Data.Entity.Core.Mapping.Update.Internal.DynamicUpdateCommand.<ExecuteAsync>d__0.MoveNext()
--- Fim do rastreamento de pilha do local anterior onde a exceção foi gerada ---
   em System.Runtime.CompilerServices.TaskAwaiter.ThrowForNonSuccess(Task task)
   em System.Runtime.CompilerServices.TaskAwaiter.HandleNonSuccessAndDebuggerNotification(Task task)
   em System.Data.Entity.Core.Mapping.Update.Internal.UpdateTranslator.<UpdateAsync>d__0.MoveNext()
================================================================================
Data: 2018-02-24 17:08:29-------------------------------------------------------
Mensagem:-----------------------------------------------------------------------
An error occurred while updating the entries. See the inner exception for details.
Source:-------------------------------------------------------------------------
mscorlib
StackTrace:---------------------------------------------------------------------
   em System.Runtime.CompilerServices.TaskAwaiter.ThrowForNonSuccess(Task task)
   em System.Runtime.CompilerServices.TaskAwaiter.HandleNonSuccessAndDebuggerNotification(Task task)
   em System.Runtime.CompilerServices.TaskAwaiter`1.GetResult()
   em FotUp.Infra.DbContext.ApplicationDbContext.<SaveChangesAsync>d__32.MoveNext() na C:\Users\vitor\Dropbox\Projetos\FotUp\FotUp\02-Infra\FotUp.Infra\DbContext\ApplicationDbContext.cs:linha 73
Mensagem:-----------------------------------------------------------------------
An error occurred while updating the entries. See the inner exception for details.
Source:-------------------------------------------------------------------------
EntityFramework
StackTrace:---------------------------------------------------------------------
   em System.Data.Entity.Core.Mapping.Update.Internal.UpdateTranslator.<UpdateAsync>d__0.MoveNext()
--- Fim do rastreamento de pilha do local anterior onde a exceção foi gerada ---
   em System.Runtime.CompilerServices.TaskAwaiter.ThrowForNonSuccess(Task task)
   em System.Runtime.CompilerServices.TaskAwaiter.HandleNonSuccessAndDebuggerNotification(Task task)
   em System.Data.Entity.Core.Objects.ObjectContext.<ExecuteInTransactionAsync>d__3d`1.MoveNext()
--- Fim do rastreamento de pilha do local anterior onde a exceção foi gerada ---
   em System.Runtime.CompilerServices.TaskAwaiter.ThrowForNonSuccess(Task task)
   em System.Runtime.CompilerServices.TaskAwaiter.HandleNonSuccessAndDebuggerNotification(Task task)
   em System.Data.Entity.Core.Objects.ObjectContext.<SaveChangesToStoreAsync>d__39.MoveNext()
--- Fim do rastreamento de pilha do local anterior onde a exceção foi gerada ---
   em System.Runtime.CompilerServices.TaskAwaiter.ThrowForNonSuccess(Task task)
   em System.Runtime.CompilerServices.TaskAwaiter.HandleNonSuccessAndDebuggerNotification(Task task)
   em System.Data.Entity.SqlServer.DefaultSqlExecutionStrategy.<ExecuteAsyncImplementation>d__9`1.MoveNext()
--- Fim do rastreamento de pilha do local anterior onde a exceção foi gerada ---
   em System.Runtime.CompilerServices.TaskAwaiter.ThrowForNonSuccess(Task task)
   em System.Runtime.CompilerServices.TaskAwaiter.HandleNonSuccessAndDebuggerNotification(Task task)
   em System.Data.Entity.Core.Objects.ObjectContext.<SaveChangesInternalAsync>d__31.MoveNext()
Mensagem:-----------------------------------------------------------------------
A conversão de um tipo de dados datetime2 em um tipo de dados datetime resultou em um valor fora do intervalo.
A instrução foi finalizada.
Source:-------------------------------------------------------------------------
.Net SqlClient Data Provider
StackTrace:---------------------------------------------------------------------
   em System.Data.SqlClient.SqlCommand.<>c.<ExecuteDbDataReaderAsync>b__174_0(Task`1 result)
   em System.Threading.Tasks.ContinuationResultTaskFromResultTask`2.InnerInvoke()
   em System.Threading.Tasks.Task.Execute()
--- Fim do rastreamento de pilha do local anterior onde a exceção foi gerada ---
   em System.Runtime.CompilerServices.TaskAwaiter.ThrowForNonSuccess(Task task)
   em System.Runtime.CompilerServices.TaskAwaiter.HandleNonSuccessAndDebuggerNotification(Task task)
   em System.Data.Entity.Utilities.TaskExtensions.CultureAwaiter`1.GetResult()
   em System.Data.Entity.Core.Mapping.Update.Internal.DynamicUpdateCommand.<ExecuteAsync>d__0.MoveNext()
--- Fim do rastreamento de pilha do local anterior onde a exceção foi gerada ---
   em System.Runtime.CompilerServices.TaskAwaiter.ThrowForNonSuccess(Task task)
   em System.Runtime.CompilerServices.TaskAwaiter.HandleNonSuccessAndDebuggerNotification(Task task)
   em System.Data.Entity.Core.Mapping.Update.Internal.UpdateTranslator.<UpdateAsync>d__0.MoveNext()
================================================================================
Data: 2018-02-24 17:10:54-------------------------------------------------------
Mensagem:-----------------------------------------------------------------------
An error occurred while updating the entries. See the inner exception for details.
Source:-------------------------------------------------------------------------
mscorlib
StackTrace:---------------------------------------------------------------------
   em System.Runtime.CompilerServices.TaskAwaiter.ThrowForNonSuccess(Task task)
   em System.Runtime.CompilerServices.TaskAwaiter.HandleNonSuccessAndDebuggerNotification(Task task)
   em System.Runtime.CompilerServices.TaskAwaiter`1.GetResult()
   em FotUp.Infra.DbContext.ApplicationDbContext.<SaveChangesAsync>d__32.MoveNext() na C:\Users\vitor\Dropbox\Projetos\FotUp\FotUp\02-Infra\FotUp.Infra\DbContext\ApplicationDbContext.cs:linha 73
Mensagem:-----------------------------------------------------------------------
An error occurred while updating the entries. See the inner exception for details.
Source:-------------------------------------------------------------------------
EntityFramework
StackTrace:---------------------------------------------------------------------
   em System.Data.Entity.Core.Mapping.Update.Internal.UpdateTranslator.<UpdateAsync>d__0.MoveNext()
--- Fim do rastreamento de pilha do local anterior onde a exceção foi gerada ---
   em System.Runtime.CompilerServices.TaskAwaiter.ThrowForNonSuccess(Task task)
   em System.Runtime.CompilerServices.TaskAwaiter.HandleNonSuccessAndDebuggerNotification(Task task)
   em System.Data.Entity.Core.Objects.ObjectContext.<ExecuteInTransactionAsync>d__3d`1.MoveNext()
--- Fim do rastreamento de pilha do local anterior onde a exceção foi gerada ---
   em System.Runtime.CompilerServices.TaskAwaiter.ThrowForNonSuccess(Task task)
   em System.Runtime.CompilerServices.TaskAwaiter.HandleNonSuccessAndDebuggerNotification(Task task)
   em System.Data.Entity.Core.Objects.ObjectContext.<SaveChangesToStoreAsync>d__39.MoveNext()
--- Fim do rastreamento de pilha do local anterior onde a exceção foi gerada ---
   em System.Runtime.CompilerServices.TaskAwaiter.ThrowForNonSuccess(Task task)
   em System.Runtime.CompilerServices.TaskAwaiter.HandleNonSuccessAndDebuggerNotification(Task task)
   em System.Data.Entity.SqlServer.DefaultSqlExecutionStrategy.<ExecuteAsyncImplementation>d__9`1.MoveNext()
--- Fim do rastreamento de pilha do local anterior onde a exceção foi gerada ---
   em System.Runtime.CompilerServices.TaskAwaiter.ThrowForNonSuccess(Task task)
   em System.Runtime.CompilerServices.TaskAwaiter.HandleNonSuccessAndDebuggerNotification(Task task)
   em System.Data.Entity.Core.Objects.ObjectContext.<SaveChangesInternalAsync>d__31.MoveNext()
Mensagem:-----------------------------------------------------------------------
A conversão de um tipo de dados datetime2 em um tipo de dados datetime resultou em um valor fora do intervalo.
A instrução foi finalizada.
Source:-------------------------------------------------------------------------
.Net SqlClient Data Provider
StackTrace:---------------------------------------------------------------------
   em System.Data.SqlClient.SqlCommand.<>c.<ExecuteDbDataReaderAsync>b__174_0(Task`1 result)
   em System.Threading.Tasks.ContinuationResultTaskFromResultTask`2.InnerInvoke()
   em System.Threading.Tasks.Task.Execute()
--- Fim do rastreamento de pilha do local anterior onde a exceção foi gerada ---
   em System.Runtime.CompilerServices.TaskAwaiter.ThrowForNonSuccess(Task task)
   em System.Runtime.CompilerServices.TaskAwaiter.HandleNonSuccessAndDebuggerNotification(Task task)
   em System.Data.Entity.Utilities.TaskExtensions.CultureAwaiter`1.GetResult()
   em System.Data.Entity.Core.Mapping.Update.Internal.DynamicUpdateCommand.<ExecuteAsync>d__0.MoveNext()
--- Fim do rastreamento de pilha do local anterior onde a exceção foi gerada ---
   em System.Runtime.CompilerServices.TaskAwaiter.ThrowForNonSuccess(Task task)
   em System.Runtime.CompilerServices.TaskAwaiter.HandleNonSuccessAndDebuggerNotification(Task task)
   em System.Data.Entity.Core.Mapping.Update.Internal.UpdateTranslator.<UpdateAsync>d__0.MoveNext()
================================================================================
Data: 2018-03-04 19:09:41-------------------------------------------------------
Mensagem:-----------------------------------------------------------------------
An error occurred while updating the entries. See the inner exception for details.
Source:-------------------------------------------------------------------------
mscorlib
StackTrace:---------------------------------------------------------------------
   em System.Runtime.CompilerServices.TaskAwaiter.ThrowForNonSuccess(Task task)
   em System.Runtime.CompilerServices.TaskAwaiter.HandleNonSuccessAndDebuggerNotification(Task task)
   em System.Runtime.CompilerServices.TaskAwaiter`1.GetResult()
   em PhotoStore.Infra.DbContext.ApplicationDbContext.<SaveChangesAsync>d__32.MoveNext() na C:\Users\vitor\Dropbox\Projetos\FotUp\PhotoStore\02-Infra\PhotoStore.Infra\DbContext\ApplicationDbContext.cs:linha 73
Mensagem:-----------------------------------------------------------------------
An error occurred while updating the entries. See the inner exception for details.
Source:-------------------------------------------------------------------------
EntityFramework
StackTrace:---------------------------------------------------------------------
   em System.Data.Entity.Core.Mapping.Update.Internal.UpdateTranslator.<UpdateAsync>d__0.MoveNext()
--- Fim do rastreamento de pilha do local anterior onde a exceção foi gerada ---
   em System.Runtime.CompilerServices.TaskAwaiter.ThrowForNonSuccess(Task task)
   em System.Runtime.CompilerServices.TaskAwaiter.HandleNonSuccessAndDebuggerNotification(Task task)
   em System.Data.Entity.Core.Objects.ObjectContext.<ExecuteInTransactionAsync>d__3d`1.MoveNext()
--- Fim do rastreamento de pilha do local anterior onde a exceção foi gerada ---
   em System.Runtime.CompilerServices.TaskAwaiter.ThrowForNonSuccess(Task task)
   em System.Runtime.CompilerServices.TaskAwaiter.HandleNonSuccessAndDebuggerNotification(Task task)
   em System.Data.Entity.Core.Objects.ObjectContext.<SaveChangesToStoreAsync>d__39.MoveNext()
--- Fim do rastreamento de pilha do local anterior onde a exceção foi gerada ---
   em System.Runtime.CompilerServices.TaskAwaiter.ThrowForNonSuccess(Task task)
   em System.Runtime.CompilerServices.TaskAwaiter.HandleNonSuccessAndDebuggerNotification(Task task)
   em System.Data.Entity.SqlServer.DefaultSqlExecutionStrategy.<ExecuteAsyncImplementation>d__9`1.MoveNext()
--- Fim do rastreamento de pilha do local anterior onde a exceção foi gerada ---
   em System.Runtime.CompilerServices.TaskAwaiter.ThrowForNonSuccess(Task task)
   em System.Runtime.CompilerServices.TaskAwaiter.HandleNonSuccessAndDebuggerNotification(Task task)
   em System.Data.Entity.Core.Objects.ObjectContext.<SaveChangesInternalAsync>d__31.MoveNext()
Mensagem:-----------------------------------------------------------------------
A instrução DELETE conflitou com a restrição do REFERENCE "FK_dbo.Produto_dbo.TipoProduto_Tipo_Id". O conflito ocorreu no banco de dados "PhotoStore", tabela "dbo.Produto", column 'Tipo_Id'.
A instrução foi finalizada.
Source:-------------------------------------------------------------------------
.Net SqlClient Data Provider
StackTrace:---------------------------------------------------------------------
   em System.Data.SqlClient.SqlConnection.OnError(SqlException exception, Boolean breakConnection, Action`1 wrapCloseInAction)
   em System.Data.SqlClient.SqlInternalConnection.OnError(SqlException exception, Boolean breakConnection, Action`1 wrapCloseInAction)
   em System.Data.SqlClient.TdsParser.ThrowExceptionAndWarning(TdsParserStateObject stateObj, Boolean callerHasConnectionLock, Boolean asyncClose)
   em System.Data.SqlClient.TdsParser.TryRun(RunBehavior runBehavior, SqlCommand cmdHandler, SqlDataReader dataStream, BulkCopySimpleResultSet bulkCopyHandler, TdsParserStateObject stateObj, Boolean& dataReady)
   em System.Data.SqlClient.SqlCommand.FinishExecuteReader(SqlDataReader ds, RunBehavior runBehavior, String resetOptionsString, Boolean isInternal, Boolean forDescribeParameterEncryption)
   em System.Data.SqlClient.SqlCommand.CompleteAsyncExecuteReader(Boolean isInternal, Boolean forDescribeParameterEncryption)
   em System.Data.SqlClient.SqlCommand.InternalEndExecuteNonQuery(IAsyncResult asyncResult, String endMethod, Boolean isInternal)
   em System.Data.SqlClient.SqlCommand.EndExecuteNonQueryInternal(IAsyncResult asyncResult)
   em System.Data.SqlClient.SqlCommand.EndExecuteNonQueryAsync(IAsyncResult asyncResult)
   em System.Threading.Tasks.TaskFactory`1.FromAsyncCoreLogic(IAsyncResult iar, Func`2 endFunction, Action`1 endAction, Task`1 promise, Boolean requiresSynchronization)
--- Fim do rastreamento de pilha do local anterior onde a exceção foi gerada ---
   em System.Runtime.CompilerServices.TaskAwaiter.ThrowForNonSuccess(Task task)
   em System.Runtime.CompilerServices.TaskAwaiter.HandleNonSuccessAndDebuggerNotification(Task task)
   em System.Data.Entity.Utilities.TaskExtensions.CultureAwaiter`1.GetResult()
   em System.Data.Entity.Core.Mapping.Update.Internal.DynamicUpdateCommand.<ExecuteAsync>d__0.MoveNext()
--- Fim do rastreamento de pilha do local anterior onde a exceção foi gerada ---
   em System.Runtime.CompilerServices.TaskAwaiter.ThrowForNonSuccess(Task task)
   em System.Runtime.CompilerServices.TaskAwaiter.HandleNonSuccessAndDebuggerNotification(Task task)
   em System.Data.Entity.Core.Mapping.Update.Internal.UpdateTranslator.<UpdateAsync>d__0.MoveNext()
================================================================================
Data: 2018-03-04 19:27:01-------------------------------------------------------
Mensagem:-----------------------------------------------------------------------
An error occurred while updating the entries. See the inner exception for details.
Source:-------------------------------------------------------------------------
mscorlib
StackTrace:---------------------------------------------------------------------
   em System.Runtime.CompilerServices.TaskAwaiter.ThrowForNonSuccess(Task task)
   em System.Runtime.CompilerServices.TaskAwaiter.HandleNonSuccessAndDebuggerNotification(Task task)
   em System.Runtime.CompilerServices.TaskAwaiter`1.GetResult()
   em PhotoStore.Infra.DbContext.ApplicationDbContext.<SaveChangesAsync>d__32.MoveNext() na C:\Users\vitor\Dropbox\Projetos\FotUp\PhotoStore\02-Infra\PhotoStore.Infra\DbContext\ApplicationDbContext.cs:linha 73
Mensagem:-----------------------------------------------------------------------
An error occurred while updating the entries. See the inner exception for details.
Source:-------------------------------------------------------------------------
EntityFramework
StackTrace:---------------------------------------------------------------------
   em System.Data.Entity.Core.Mapping.Update.Internal.UpdateTranslator.<UpdateAsync>d__0.MoveNext()
--- Fim do rastreamento de pilha do local anterior onde a exceção foi gerada ---
   em System.Runtime.CompilerServices.TaskAwaiter.ThrowForNonSuccess(Task task)
   em System.Runtime.CompilerServices.TaskAwaiter.HandleNonSuccessAndDebuggerNotification(Task task)
   em System.Data.Entity.Core.Objects.ObjectContext.<ExecuteInTransactionAsync>d__3d`1.MoveNext()
--- Fim do rastreamento de pilha do local anterior onde a exceção foi gerada ---
   em System.Runtime.CompilerServices.TaskAwaiter.ThrowForNonSuccess(Task task)
   em System.Runtime.CompilerServices.TaskAwaiter.HandleNonSuccessAndDebuggerNotification(Task task)
   em System.Data.Entity.Core.Objects.ObjectContext.<SaveChangesToStoreAsync>d__39.MoveNext()
--- Fim do rastreamento de pilha do local anterior onde a exceção foi gerada ---
   em System.Runtime.CompilerServices.TaskAwaiter.ThrowForNonSuccess(Task task)
   em System.Runtime.CompilerServices.TaskAwaiter.HandleNonSuccessAndDebuggerNotification(Task task)
   em System.Data.Entity.SqlServer.DefaultSqlExecutionStrategy.<ExecuteAsyncImplementation>d__9`1.MoveNext()
--- Fim do rastreamento de pilha do local anterior onde a exceção foi gerada ---
   em System.Runtime.CompilerServices.TaskAwaiter.ThrowForNonSuccess(Task task)
   em System.Runtime.CompilerServices.TaskAwaiter.HandleNonSuccessAndDebuggerNotification(Task task)
   em System.Data.Entity.Core.Objects.ObjectContext.<SaveChangesInternalAsync>d__31.MoveNext()
Mensagem:-----------------------------------------------------------------------
Não é possível inserir uma linha de chave duplicada no objeto 'dbo.TipoProduto' com índice exclusivo 'IX_Nome'. O valor de chave duplicada é (teste 5).
A instrução foi finalizada.
Source:-------------------------------------------------------------------------
.Net SqlClient Data Provider
StackTrace:---------------------------------------------------------------------
   em System.Data.SqlClient.SqlCommand.<>c.<ExecuteDbDataReaderAsync>b__174_0(Task`1 result)
   em System.Threading.Tasks.ContinuationResultTaskFromResultTask`2.InnerInvoke()
   em System.Threading.Tasks.Task.Execute()
--- Fim do rastreamento de pilha do local anterior onde a exceção foi gerada ---
   em System.Runtime.CompilerServices.TaskAwaiter.ThrowForNonSuccess(Task task)
   em System.Runtime.CompilerServices.TaskAwaiter.HandleNonSuccessAndDebuggerNotification(Task task)
   em System.Data.Entity.Utilities.TaskExtensions.CultureAwaiter`1.GetResult()
   em System.Data.Entity.Core.Mapping.Update.Internal.DynamicUpdateCommand.<ExecuteAsync>d__0.MoveNext()
--- Fim do rastreamento de pilha do local anterior onde a exceção foi gerada ---
   em System.Runtime.CompilerServices.TaskAwaiter.ThrowForNonSuccess(Task task)
   em System.Runtime.CompilerServices.TaskAwaiter.HandleNonSuccessAndDebuggerNotification(Task task)
   em System.Data.Entity.Core.Mapping.Update.Internal.UpdateTranslator.<UpdateAsync>d__0.MoveNext()
================================================================================
Data: 2018-03-04 19:28:09-------------------------------------------------------
Mensagem:-----------------------------------------------------------------------
An error occurred while updating the entries. See the inner exception for details.
Source:-------------------------------------------------------------------------
mscorlib
StackTrace:---------------------------------------------------------------------
   em System.Runtime.CompilerServices.TaskAwaiter.ThrowForNonSuccess(Task task)
   em System.Runtime.CompilerServices.TaskAwaiter.HandleNonSuccessAndDebuggerNotification(Task task)
   em System.Runtime.CompilerServices.TaskAwaiter`1.GetResult()
   em PhotoStore.Infra.DbContext.ApplicationDbContext.<SaveChangesAsync>d__32.MoveNext() na C:\Users\vitor\Dropbox\Projetos\FotUp\PhotoStore\02-Infra\PhotoStore.Infra\DbContext\ApplicationDbContext.cs:linha 73
Mensagem:-----------------------------------------------------------------------
An error occurred while updating the entries. See the inner exception for details.
Source:-------------------------------------------------------------------------
EntityFramework
StackTrace:---------------------------------------------------------------------
   em System.Data.Entity.Core.Mapping.Update.Internal.UpdateTranslator.<UpdateAsync>d__0.MoveNext()
--- Fim do rastreamento de pilha do local anterior onde a exceção foi gerada ---
   em System.Runtime.CompilerServices.TaskAwaiter.ThrowForNonSuccess(Task task)
   em System.Runtime.CompilerServices.TaskAwaiter.HandleNonSuccessAndDebuggerNotification(Task task)
   em System.Data.Entity.Core.Objects.ObjectContext.<ExecuteInTransactionAsync>d__3d`1.MoveNext()
--- Fim do rastreamento de pilha do local anterior onde a exceção foi gerada ---
   em System.Runtime.CompilerServices.TaskAwaiter.ThrowForNonSuccess(Task task)
   em System.Runtime.CompilerServices.TaskAwaiter.HandleNonSuccessAndDebuggerNotification(Task task)
   em System.Data.Entity.Core.Objects.ObjectContext.<SaveChangesToStoreAsync>d__39.MoveNext()
--- Fim do rastreamento de pilha do local anterior onde a exceção foi gerada ---
   em System.Runtime.CompilerServices.TaskAwaiter.ThrowForNonSuccess(Task task)
   em System.Runtime.CompilerServices.TaskAwaiter.HandleNonSuccessAndDebuggerNotification(Task task)
   em System.Data.Entity.SqlServer.DefaultSqlExecutionStrategy.<ExecuteAsyncImplementation>d__9`1.MoveNext()
--- Fim do rastreamento de pilha do local anterior onde a exceção foi gerada ---
   em System.Runtime.CompilerServices.TaskAwaiter.ThrowForNonSuccess(Task task)
   em System.Runtime.CompilerServices.TaskAwaiter.HandleNonSuccessAndDebuggerNotification(Task task)
   em System.Data.Entity.Core.Objects.ObjectContext.<SaveChangesInternalAsync>d__31.MoveNext()
Mensagem:-----------------------------------------------------------------------
Não é possível inserir uma linha de chave duplicada no objeto 'dbo.TipoProduto' com índice exclusivo 'IX_Nome'. O valor de chave duplicada é (teste 5).
A instrução foi finalizada.
Source:-------------------------------------------------------------------------
.Net SqlClient Data Provider
StackTrace:---------------------------------------------------------------------
   em System.Data.SqlClient.SqlCommand.<>c.<ExecuteDbDataReaderAsync>b__174_0(Task`1 result)
   em System.Threading.Tasks.ContinuationResultTaskFromResultTask`2.InnerInvoke()
   em System.Threading.Tasks.Task.Execute()
--- Fim do rastreamento de pilha do local anterior onde a exceção foi gerada ---
   em System.Runtime.CompilerServices.TaskAwaiter.ThrowForNonSuccess(Task task)
   em System.Runtime.CompilerServices.TaskAwaiter.HandleNonSuccessAndDebuggerNotification(Task task)
   em System.Data.Entity.Utilities.TaskExtensions.CultureAwaiter`1.GetResult()
   em System.Data.Entity.Core.Mapping.Update.Internal.DynamicUpdateCommand.<ExecuteAsync>d__0.MoveNext()
--- Fim do rastreamento de pilha do local anterior onde a exceção foi gerada ---
   em System.Runtime.CompilerServices.TaskAwaiter.ThrowForNonSuccess(Task task)
   em System.Runtime.CompilerServices.TaskAwaiter.HandleNonSuccessAndDebuggerNotification(Task task)
   em System.Data.Entity.Core.Mapping.Update.Internal.UpdateTranslator.<UpdateAsync>d__0.MoveNext()
================================================================================
Data: 2018-03-04 19:30:00-------------------------------------------------------
Mensagem:-----------------------------------------------------------------------
An error occurred while updating the entries. See the inner exception for details.
Source:-------------------------------------------------------------------------
mscorlib
StackTrace:---------------------------------------------------------------------
   em System.Runtime.CompilerServices.TaskAwaiter.ThrowForNonSuccess(Task task)
   em System.Runtime.CompilerServices.TaskAwaiter.HandleNonSuccessAndDebuggerNotification(Task task)
   em System.Runtime.CompilerServices.TaskAwaiter`1.GetResult()
   em PhotoStore.Infra.DbContext.ApplicationDbContext.<SaveChangesAsync>d__32.MoveNext() na C:\Users\vitor\Dropbox\Projetos\FotUp\PhotoStore\02-Infra\PhotoStore.Infra\DbContext\ApplicationDbContext.cs:linha 73
Mensagem:-----------------------------------------------------------------------
An error occurred while updating the entries. See the inner exception for details.
Source:-------------------------------------------------------------------------
EntityFramework
StackTrace:---------------------------------------------------------------------
   em System.Data.Entity.Core.Mapping.Update.Internal.UpdateTranslator.<UpdateAsync>d__0.MoveNext()
--- Fim do rastreamento de pilha do local anterior onde a exceção foi gerada ---
   em System.Runtime.CompilerServices.TaskAwaiter.ThrowForNonSuccess(Task task)
   em System.Runtime.CompilerServices.TaskAwaiter.HandleNonSuccessAndDebuggerNotification(Task task)
   em System.Data.Entity.Core.Objects.ObjectContext.<ExecuteInTransactionAsync>d__3d`1.MoveNext()
--- Fim do rastreamento de pilha do local anterior onde a exceção foi gerada ---
   em System.Runtime.CompilerServices.TaskAwaiter.ThrowForNonSuccess(Task task)
   em System.Runtime.CompilerServices.TaskAwaiter.HandleNonSuccessAndDebuggerNotification(Task task)
   em System.Data.Entity.Core.Objects.ObjectContext.<SaveChangesToStoreAsync>d__39.MoveNext()
--- Fim do rastreamento de pilha do local anterior onde a exceção foi gerada ---
   em System.Runtime.CompilerServices.TaskAwaiter.ThrowForNonSuccess(Task task)
   em System.Runtime.CompilerServices.TaskAwaiter.HandleNonSuccessAndDebuggerNotification(Task task)
   em System.Data.Entity.SqlServer.DefaultSqlExecutionStrategy.<ExecuteAsyncImplementation>d__9`1.MoveNext()
--- Fim do rastreamento de pilha do local anterior onde a exceção foi gerada ---
   em System.Runtime.CompilerServices.TaskAwaiter.ThrowForNonSuccess(Task task)
   em System.Runtime.CompilerServices.TaskAwaiter.HandleNonSuccessAndDebuggerNotification(Task task)
   em System.Data.Entity.Core.Objects.ObjectContext.<SaveChangesInternalAsync>d__31.MoveNext()
Mensagem:-----------------------------------------------------------------------
Não é possível inserir uma linha de chave duplicada no objeto 'dbo.TipoProduto' com índice exclusivo 'IX_Nome'. O valor de chave duplicada é (teste 5).
A instrução foi finalizada.
Source:-------------------------------------------------------------------------
.Net SqlClient Data Provider
StackTrace:---------------------------------------------------------------------
   em System.Data.SqlClient.SqlCommand.<>c.<ExecuteDbDataReaderAsync>b__174_0(Task`1 result)
   em System.Threading.Tasks.ContinuationResultTaskFromResultTask`2.InnerInvoke()
   em System.Threading.Tasks.Task.Execute()
--- Fim do rastreamento de pilha do local anterior onde a exceção foi gerada ---
   em System.Runtime.CompilerServices.TaskAwaiter.ThrowForNonSuccess(Task task)
   em System.Runtime.CompilerServices.TaskAwaiter.HandleNonSuccessAndDebuggerNotification(Task task)
   em System.Data.Entity.Utilities.TaskExtensions.CultureAwaiter`1.GetResult()
   em System.Data.Entity.Core.Mapping.Update.Internal.DynamicUpdateCommand.<ExecuteAsync>d__0.MoveNext()
--- Fim do rastreamento de pilha do local anterior onde a exceção foi gerada ---
   em System.Runtime.CompilerServices.TaskAwaiter.ThrowForNonSuccess(Task task)
   em System.Runtime.CompilerServices.TaskAwaiter.HandleNonSuccessAndDebuggerNotification(Task task)
   em System.Data.Entity.Core.Mapping.Update.Internal.UpdateTranslator.<UpdateAsync>d__0.MoveNext()
================================================================================
Data: 2018-03-04 19:32:20-------------------------------------------------------
Mensagem:-----------------------------------------------------------------------
An error occurred while updating the entries. See the inner exception for details.
Source:-------------------------------------------------------------------------
mscorlib
StackTrace:---------------------------------------------------------------------
   em System.Runtime.CompilerServices.TaskAwaiter.ThrowForNonSuccess(Task task)
   em System.Runtime.CompilerServices.TaskAwaiter.HandleNonSuccessAndDebuggerNotification(Task task)
   em System.Runtime.CompilerServices.TaskAwaiter`1.GetResult()
   em PhotoStore.Infra.DbContext.ApplicationDbContext.<SaveChangesAsync>d__32.MoveNext() na C:\Users\vitor\Dropbox\Projetos\FotUp\PhotoStore\02-Infra\PhotoStore.Infra\DbContext\ApplicationDbContext.cs:linha 73
Mensagem:-----------------------------------------------------------------------
An error occurred while updating the entries. See the inner exception for details.
Source:-------------------------------------------------------------------------
EntityFramework
StackTrace:---------------------------------------------------------------------
   em System.Data.Entity.Core.Mapping.Update.Internal.UpdateTranslator.<UpdateAsync>d__0.MoveNext()
--- Fim do rastreamento de pilha do local anterior onde a exceção foi gerada ---
   em System.Runtime.CompilerServices.TaskAwaiter.ThrowForNonSuccess(Task task)
   em System.Runtime.CompilerServices.TaskAwaiter.HandleNonSuccessAndDebuggerNotification(Task task)
   em System.Data.Entity.Core.Objects.ObjectContext.<ExecuteInTransactionAsync>d__3d`1.MoveNext()
--- Fim do rastreamento de pilha do local anterior onde a exceção foi gerada ---
   em System.Runtime.CompilerServices.TaskAwaiter.ThrowForNonSuccess(Task task)
   em System.Runtime.CompilerServices.TaskAwaiter.HandleNonSuccessAndDebuggerNotification(Task task)
   em System.Data.Entity.Core.Objects.ObjectContext.<SaveChangesToStoreAsync>d__39.MoveNext()
--- Fim do rastreamento de pilha do local anterior onde a exceção foi gerada ---
   em System.Runtime.CompilerServices.TaskAwaiter.ThrowForNonSuccess(Task task)
   em System.Runtime.CompilerServices.TaskAwaiter.HandleNonSuccessAndDebuggerNotification(Task task)
   em System.Data.Entity.SqlServer.DefaultSqlExecutionStrategy.<ExecuteAsyncImplementation>d__9`1.MoveNext()
--- Fim do rastreamento de pilha do local anterior onde a exceção foi gerada ---
   em System.Runtime.CompilerServices.TaskAwaiter.ThrowForNonSuccess(Task task)
   em System.Runtime.CompilerServices.TaskAwaiter.HandleNonSuccessAndDebuggerNotification(Task task)
   em System.Data.Entity.Core.Objects.ObjectContext.<SaveChangesInternalAsync>d__31.MoveNext()
Mensagem:-----------------------------------------------------------------------
Não é possível inserir uma linha de chave duplicada no objeto 'dbo.TipoProduto' com índice exclusivo 'IX_Nome'. O valor de chave duplicada é (teste 5).
A instrução foi finalizada.
Source:-------------------------------------------------------------------------
.Net SqlClient Data Provider
StackTrace:---------------------------------------------------------------------
   em System.Data.SqlClient.SqlCommand.<>c.<ExecuteDbDataReaderAsync>b__174_0(Task`1 result)
   em System.Threading.Tasks.ContinuationResultTaskFromResultTask`2.InnerInvoke()
   em System.Threading.Tasks.Task.Execute()
--- Fim do rastreamento de pilha do local anterior onde a exceção foi gerada ---
   em System.Runtime.CompilerServices.TaskAwaiter.ThrowForNonSuccess(Task task)
   em System.Runtime.CompilerServices.TaskAwaiter.HandleNonSuccessAndDebuggerNotification(Task task)
   em System.Data.Entity.Utilities.TaskExtensions.CultureAwaiter`1.GetResult()
   em System.Data.Entity.Core.Mapping.Update.Internal.DynamicUpdateCommand.<ExecuteAsync>d__0.MoveNext()
--- Fim do rastreamento de pilha do local anterior onde a exceção foi gerada ---
   em System.Runtime.CompilerServices.TaskAwaiter.ThrowForNonSuccess(Task task)
   em System.Runtime.CompilerServices.TaskAwaiter.HandleNonSuccessAndDebuggerNotification(Task task)
   em System.Data.Entity.Core.Mapping.Update.Internal.UpdateTranslator.<UpdateAsync>d__0.MoveNext()
================================================================================
Data: 2018-03-04 19:33:03-------------------------------------------------------
Mensagem:-----------------------------------------------------------------------
An error occurred while updating the entries. See the inner exception for details.
Source:-------------------------------------------------------------------------
mscorlib
StackTrace:---------------------------------------------------------------------
   em System.Runtime.CompilerServices.TaskAwaiter.ThrowForNonSuccess(Task task)
   em System.Runtime.CompilerServices.TaskAwaiter.HandleNonSuccessAndDebuggerNotification(Task task)
   em System.Runtime.CompilerServices.TaskAwaiter`1.GetResult()
   em PhotoStore.Infra.DbContext.ApplicationDbContext.<SaveChangesAsync>d__32.MoveNext() na C:\Users\vitor\Dropbox\Projetos\FotUp\PhotoStore\02-Infra\PhotoStore.Infra\DbContext\ApplicationDbContext.cs:linha 73
Mensagem:-----------------------------------------------------------------------
An error occurred while updating the entries. See the inner exception for details.
Source:-------------------------------------------------------------------------
EntityFramework
StackTrace:---------------------------------------------------------------------
   em System.Data.Entity.Core.Mapping.Update.Internal.UpdateTranslator.<UpdateAsync>d__0.MoveNext()
--- Fim do rastreamento de pilha do local anterior onde a exceção foi gerada ---
   em System.Runtime.CompilerServices.TaskAwaiter.ThrowForNonSuccess(Task task)
   em System.Runtime.CompilerServices.TaskAwaiter.HandleNonSuccessAndDebuggerNotification(Task task)
   em System.Data.Entity.Core.Objects.ObjectContext.<ExecuteInTransactionAsync>d__3d`1.MoveNext()
--- Fim do rastreamento de pilha do local anterior onde a exceção foi gerada ---
   em System.Runtime.CompilerServices.TaskAwaiter.ThrowForNonSuccess(Task task)
   em System.Runtime.CompilerServices.TaskAwaiter.HandleNonSuccessAndDebuggerNotification(Task task)
   em System.Data.Entity.Core.Objects.ObjectContext.<SaveChangesToStoreAsync>d__39.MoveNext()
--- Fim do rastreamento de pilha do local anterior onde a exceção foi gerada ---
   em System.Runtime.CompilerServices.TaskAwaiter.ThrowForNonSuccess(Task task)
   em System.Runtime.CompilerServices.TaskAwaiter.HandleNonSuccessAndDebuggerNotification(Task task)
   em System.Data.Entity.SqlServer.DefaultSqlExecutionStrategy.<ExecuteAsyncImplementation>d__9`1.MoveNext()
--- Fim do rastreamento de pilha do local anterior onde a exceção foi gerada ---
   em System.Runtime.CompilerServices.TaskAwaiter.ThrowForNonSuccess(Task task)
   em System.Runtime.CompilerServices.TaskAwaiter.HandleNonSuccessAndDebuggerNotification(Task task)
   em System.Data.Entity.Core.Objects.ObjectContext.<SaveChangesInternalAsync>d__31.MoveNext()
Mensagem:-----------------------------------------------------------------------
Não é possível inserir uma linha de chave duplicada no objeto 'dbo.TipoProduto' com índice exclusivo 'IX_Nome'. O valor de chave duplicada é (teste 5).
A instrução foi finalizada.
Source:-------------------------------------------------------------------------
.Net SqlClient Data Provider
StackTrace:---------------------------------------------------------------------
   em System.Data.SqlClient.SqlCommand.<>c.<ExecuteDbDataReaderAsync>b__174_0(Task`1 result)
   em System.Threading.Tasks.ContinuationResultTaskFromResultTask`2.InnerInvoke()
   em System.Threading.Tasks.Task.Execute()
--- Fim do rastreamento de pilha do local anterior onde a exceção foi gerada ---
   em System.Runtime.CompilerServices.TaskAwaiter.ThrowForNonSuccess(Task task)
   em System.Runtime.CompilerServices.TaskAwaiter.HandleNonSuccessAndDebuggerNotification(Task task)
   em System.Data.Entity.Utilities.TaskExtensions.CultureAwaiter`1.GetResult()
   em System.Data.Entity.Core.Mapping.Update.Internal.DynamicUpdateCommand.<ExecuteAsync>d__0.MoveNext()
--- Fim do rastreamento de pilha do local anterior onde a exceção foi gerada ---
   em System.Runtime.CompilerServices.TaskAwaiter.ThrowForNonSuccess(Task task)
   em System.Runtime.CompilerServices.TaskAwaiter.HandleNonSuccessAndDebuggerNotification(Task task)
   em System.Data.Entity.Core.Mapping.Update.Internal.UpdateTranslator.<UpdateAsync>d__0.MoveNext()
================================================================================
